Workbook
Name approval_rate: ASSUMPTIONS!$B$26
Name avg_loan_size: ASSUMPTIONS!$B$15
Name avg_term_months: ASSUMPTIONS!$B$18
Name CAC_blended: ASSUMPTIONS!$B$31
Name CAC_organic: ASSUMPTIONS!$B$30
Name CAC_paid: ASSUMPTIONS!$B$29
Name churn_rate: ASSUMPTIONS!$B$28
Name cost_of_debt: ASSUMPTIONS!$B$6
Name equity_ratio: ASSUMPTIONS!$B$7
Name exit_multiple_ebitda: ASSUMPTIONS!$B$12
Name inflation_elasticity: ASSUMPTIONS!$B$48
Name LGD_nearprime: ASSUMPTIONS!$B$38
Name LGD_prime: ASSUMPTIONS!$B$37
Name LGD_recession_uplift: ASSUMPTIONS!$B$50
Name LGD_subprime: ASSUMPTIONS!$B$39
Name monthly_growth_rate: ASSUMPTIONS!$B$25
Name origination_fee: ASSUMPTIONS!$B$20
Name PD_nearprime: ASSUMPTIONS!$B$35
Name PD_prime: ASSUMPTIONS!$B$34
Name PD_subprime: ASSUMPTIONS!$B$36
Name portfolio_LGD: ASSUMPTIONS!$B$44
Name portfolio_PD: ASSUMPTIONS!$B$43
Name rate_elasticity: ASSUMPTIONS!$B$49
Name repeat_rate: ASSUMPTIONS!$B$27
Name share_nearprime: ASSUMPTIONS!$B$41
Name share_prime: ASSUMPTIONS!$B$40
Name share_subprime: ASSUMPTIONS!$B$42
Name target_IRR: ASSUMPTIONS!$B$11
Name tax_rate: ASSUMPTIONS!$B$10
Name unemp_elasticity: ASSUMPTIONS!$B$47

Sheet ASSUMPTIONS
A1: KENYA DIGITAL LENDING — INVESTMENT MODEL
A2: Assumptions Sheet — All inputs reference this sheet
A3: Last updated: February 2026
A5: BLOCK 1 — CAPITAL AND FUNDING STRUCTURE
A6: cost_of_debt_annual | B6: 0.14 | C6: % decimal | D6: CBK avarage lending rate 2025
A7: equity_required_ratio | B7: 0.3 | C7: % decimal | D7: 30% equity 70% debt structure
A8: warehouse_facility_limit_kes_m | B8: 500 | C8: KES Millions | D8: Initial facility assumption
A9: servicing_fee_pct | B9: 0.02 | C9: % decimal | D9: 2% of loan
A10: tax_rate | B10: 0.3 | C10: % decimal | D10: Kenya corporate tax rate
A11: target_IRR | B11: 0.25 | C11: % decimal | D11: Minimum PE hurdle rate
A12: exit_multiple_editda | B12: 8 | C12: X | D12: Digital lender comparable exits
A14: BLOCK 2 — PRODUCT DESIGN
A15: avg_loan_size_kes | B15: 15000 | C15: KES | D15: FinAccess 2021 median digital loan
A16: min_loan_size_kes | B16: 500 | C16: KES | D16: Regulatory minimum
A17: max_loan_size_kes | B17: 100000 | C17: KES | D17: Risk appetite ceiling
A18: avg_term_months | B18: 3 | C18: Months | D18: Short term consumer digital lending
A19: grace_period_days | B19: 3 | C19: Days | D19: Industry standard
A20: origination_fee_pct | B20: 0.06 | C20: % decimal | D20: 6% origination fee
A21: late_fee_pct | B21: 0.01 | C21: % decimal | D21: 1% per week late
A22: collection_cost_per_default_kes | B22: 2500 | C22: KES | D22: Field collection estimate
A24: BLOCK 3 — GROWTH ENGINE
A25: monthly_customer_growth_rate | B25: 0.08 | C25: % decimal | D25: 8% MoM in ramp phase
A26: approval_rate | B26: 0.55 | C26: % decimal | D26: 55% of applicants approved
A27: repeat_borrow_rate | B27: 0.65 | C27: % decimal | D27: 65% repeat within 90 days
A28: churn_rate | B28: 0.12 | C28: % decimal | D28: 12% annual churn
A29: CAC_paid_kes | B29: 850 | C29: KES | D29: Paid digital acquisition cost
A30: CAC_organic_kes | B30: 320 | C30: KES | D30: Organic referral cost
A31: CAC_blended_kes | B31: =(B29*0.6)+(B30*0.4) -> 638 | C31: KES | D31: See formula in cell B31
A33: BLOCK 4 — CREDIT RISK PARAMETERS | D33: These will be updated when Python risk model outputs are complete. Current values are calibrated estimates based on CBK NPL data
A34: PD_prime | B34: 0.032 | C34: % decimal | D34: Calibrated to CBK NPL-prime segment
A35: PD_nearprime | B35: 0.077 | C35: % decimal | D35: Calibrated to CBK NPL-near prime
A36: PD_subprime | B36: 0.2006 | C36: % decimal | D36: Calobrated to CBK NPL-subprime
A37: LGD_prime | B37: 0.35 | C37: % decimal | D37: 35% loss given default-Prime
A38: LGD_nearprime | B38: 0.45 | C38: % decimal | D38: 45% loss given default-near prime
A39: LGD_subprime | B39: 0.6 | C39: % decimal | D39: 60% loss given default - subprime
A40: portfolio_share_prime | B40: 0.35 | C40: % decimal | D40: 35% of portfolio - prime
A41: portfolio_share_nearprime | B41: 0.45 | C41: % decimal | D41: 45% of portfolio - near prime
A42: portfolio_share_subprime | B42: 0.2 | C42: % decimal | D42: 20% of portfolio - subprime
A43: portfolio_weighted_PD | B43: =(B34*B40)+(B35*B41)+(B36*B42) -> 0.08597 | C43: % decimal | D43: Weighted avg across segments
A44: portfolio_weighted_LGD | B44: =(B37*B40)+(B38*B41)+(B39*B42) -> 0.445 | C44: % decimal | D44: Weighted avg across segments
...

Sheet MARKET_MODEL
A1: MARKET MODEL — Borrower Acquisition and Loan Demand Projection
A2: 36 Month Rolling Forecast | Base Case
A4: Metric | B4: Month 0 | C4: Month 1 | D4: Month 2 | E4: Month 3 | F4: Month 4 | G4: Month 5 | H4: Month 6 | I4: Month 7 | J4: Month 8 | K4: Month 9 | L4: Month 10 | M4: Month 11 | N4: Month 12 | O4: Month 13 | P4: Month 14 | Q4: Month 15 | R4: Month 16 | S4: Month 17 | T4: Month 18 | U4: Month 19 | V4: Month 20 | W4: Month 21 | X4: Month 22 | Y4: Month 23 | Z4: Month 24 | AA4: Month 25 | AB4: Month 26 | AC4: Month 27 | AD4: Month 28 | AE4: Month 29 | AF4: Month 30 | AG4: Month 31 | AH4: Month 32 | AI4: Month 33 | AJ4: Month 34 | AK4: Month 35 | AL4: Month 36
A6: — POPULATION FUNNEL —
A7: adult_population_2026 | B7: 34500000 | C7: =$B$7 -> 34500000 | D7: =$B$7 -> 34500000 | E7: =$B$7 -> 34500000 | F7: =$B$7 -> 34500000 | G7: =$B$7 -> 34500000 | H7: =$B$7 -> 34500000 | I7: =$B$7 -> 34500000 | J7: =$B$7 -> 34500000 | ... AL7: =$B$7 -> 34500000
A8: mpesa_penetration_rate | B8: 1.01
A9: digitally_reachable | B9: =B7*$B$8 -> 34845000 | C9: =C7*$B$8 -> 34845000 | D9: =D7*$B$8 -> 34845000 | E9: =E7*$B$8 -> 34845000 | F9: =F7*$B$8 -> 34845000 | G9: =G7*$B$8 -> 34845000 | H9: =H7*$B$8 -> 34845000 | I9: =I7*$B$8 -> 34845000 | ... AL9: =AL7*$B$8 -> 34845000
A10: addressable_approved_pool | B10: =B9*approval_rate -> 19164750 | C10: =C9*approval_rate -> 19164750 | D10: =D9*approval_rate -> 19164750 | E10: =E9*approval_rate -> 19164750 | F10: =F9*approval_rate -> 19164750 | G10: =G9*approval_rate -> 19164750 | H10: =H9*approval_rate -> 19164750 | I10: =I9*approval_rate -> 19164750 | ... AL10: =AL9*approval_rate -> 19164750
A11: market_share_pct | B11: 0.001 | C11: =B11*(1+monthly_growth_rate) -> 0.00108 | D11: =C11*(1+monthly_growth_rate) -> 0.0011664 | E11: =D11*(1+monthly_growth_rate) -> 0.001259712 | F11: =E11*(1+monthly_growth_rate) -> 0.001360489 | G11: =F11*(1+monthly_growth_rate) -> 0.0014693281 | H11: =G11*(1+monthly_growth_rate) -> 0.0015868743 | I11: =H11*(1+monthly_growth_rate) -> 0.0017138243 | J11: =I11*(1+monthly_growth_rate) -> 0.0018509302 | ... AL11: =AK11*(1+monthly_growth_rate) -> 0.015968172
A12: active_borrowers | B12: =B10*B11 -> 19164.75 | C12: =C10*C11 -> 20697.93 | D12: =D10*D11 -> 22353.764 | E12: =E10*E11 -> 24142.066 | F12: =F10*F11 -> 26073.431 | G12: =G10*G11 -> 28159.305 | H12: =H10*H11 -> 30412.05 | I12: =I10*I11 -> 32845.014 | ... AL12: =AL10*AL11 -> 306026.02
A14: — LOAN ORIGINATION —
A15: new_borrowers | B15: =B12 -> 19164.75 | C15: {=MAX(C12-B12*(1-churn_rate),0)} -> 3832.95 | D15: {=MAX(D12-C12*(1-churn_rate),0)} -> 4139.586 | E15: {=MAX(E12-D12*(1-churn_rate),0)} -> 4470.7529 | F15: {=MAX(F12-E12*(1-churn_rate),0)} -> 4828.4131 | G15: {=MAX(G12-F12*(1-churn_rate),0)} -> 5214.6862 | H15: {=MAX(H12-G12*(1-churn_rate),0)} -> 5631.8611 | I15: {=MAX(I12-H12*(1-churn_rate),0)} -> 6082.4099 | J15: {=MAX(J12-I12*(1-churn_rate),0)} -> 6569.0027 | ... AL15: {=MAX(AL12-AK12*(1-churn_rate),0)} -> 56671.485
A16: repeat_borrowers | B16: 0 | C16: =B12*repeat_rate -> 12457.087 | D16: =C12*repeat_rate -> 13453.655 | E16: =D12*repeat_rate -> 14529.947 | F16: =E12*repeat_rate -> 15692.343 | G16: =F12*repeat_rate -> 16947.73 | H16: =G12*repeat_rate -> 18303.548 | I16: =H12*repeat_rate -> 19767.832 | J16: =I12*repeat_rate -> 21349.259 | ... AL16: =AK12*repeat_rate -> 184182.33
A17: loans_originated | B17: =B15+B16 -> 19164.75 | C17: =C15+C16 -> 16290.038 | D17: =D15+D16 -> 17593.241 | E17: =E15+E16 -> 19000.7 | F17: =F15+F16 -> 20520.756 | G17: =G15+G16 -> 22162.416 | H17: =H15+H16 -> 23935.409 | I17: =I15+I16 -> 25850.242 | ... AL17: =AL15+AL16 -> 240853.81
A18: principal_originated_kes | B18: =B17*avg_loan_size -> 287471250 | C18: =C17*avg_loan_size -> 2.4435056e+08 | D18: =D17*avg_loan_size -> 2.6389861e+08 | E18: =E17*avg_loan_size -> 2.850105e+08 | F18: =F17*avg_loan_size -> 3.0781134e+08 | G18: =G17*avg_loan_size -> 3.3243624e+08 | H18: =H17*avg_loan_size -> 3.5903114e+08 | I18: =I17*avg_loan_size -> 3.8775363e+08 | ... AL18: =AL17*avg_loan_size -> 3.6128072e+09
A20: — CUMULATIVE SUMMARY —
A21: cumulative_loans_issued | B21: =B17 -> 19164.75 | C21: =C17+B21 -> 35454.787 | D21: =D17+C21 -> 53048.028 | E21: =E17+D21 -> 72048.728 | F21: =F17+E21 -> 92569.483 | G21: =G17+F21 -> 114731.9 | H21: =H17+G21 -> 138667.31 | I21: =I17+H21 -> 164517.55 | J21: =J17+I21 -> 192435.81 | ... AL21: =AL17+AK21 -> 3067065.8
A22: cumulative_principal_kes_m | B22: =B18/1000000 -> 287.47125 | C22: =(C18/1000000)+B22 -> 531.82181 | D22: =(D18/1000000)+C22 -> 795.72042 | E22: =(E18/1000000)+D22 -> 1080.7309 | F22: =(F18/1000000)+E22 -> 1388.5423 | G22: =(G18/1000000)+F22 -> 1720.9785 | H22: =(H18/1000000)+G22 -> 2080.0096 | I22: =(I18/1000000)+H22 -> 2467.7633 | J22: =(J18/1000000)+I22 -> 2886.5372 | ... AL22: =(AL18/1000000)+AK22 -> 46005.986

Sheet RISK_SEGMENTS
A1: RISK SEGMENTATION — Python Model Outputs
A2: Source: notebooks/03_borrower_risk_model.ipynb Last updated: February 2026
A4: segment | B4: portfolio share | C4: PD | D4: LGD | E4: expected_loss | F4: avg_loan_size_multiplier | G4: recommended_APR | H4: max_loan_size_kes
A5: Prime | B5: =share_prime -> 0.35 | C5: =PD_prime -> 0.032 | D5: =LGD_prime -> 0.35 | E5: =C5*D5 -> 0.0112 | F5: 1.2 | G5: =cost_of_debt+origination_fee+E5+0.08 -> 0.2912 | H5: 100000
A6: Near Prime | B6: =share_nearprime -> 0.45 | C6: =PD_nearprime -> 0.077 | D6: =LGD_nearprime -> 0.45 | E6: =C6*D6 -> 0.03465 | F6: 1 | G6: =cost_of_debt+origination_fee+E6+0.08 -> 0.31465 | H6: 50000
A7: Subprime | B7: =share_subprime -> 0.2 | C7: =PD_subprime -> 0.2006 | D7: =LGD_subprime -> 0.6 | E7: =C7*D7 -> 0.12036 | F7: 0.7 | G7: =cost_of_debt+origination_fee+E7+0.08 -> 0.40036 | H7: 25000
A9: PORTFOLIO WEIGHTED | B9: =SUM(B5:B7) -> 1 | C9: =portfolio_PD -> 0.08597 | D9: =portfolio_LGD -> 0.445 | E9: =C9*D9 -> 0.03825665 | G9: =cost_of_debt+origination_fee+E9+0.08 -> 0.31825665

Sheet LOAN_CASHFLOWS
A1: LOAN CASHFLOW ENGINE — Single Cohort Model
A2: Models one cohort from origination through full repayment or default
A4: COHORT INPUTS
A5: cohort_loan_count | B5: =MARKET_MODEL!B17 -> 19164.75
A6: avg_loan_size_kes | B6: =avg_loan_size -> 15000
A7: principal_total_kes | B7: =B5*B6 -> 287471250
A8: APR_charged_to_borrower | B8: =RISK_SEGMENTS!G9 -> 0.31825665
A9: monthly_rate_borrower | B9: =B8/12 -> 0.026521388
A10: term_months | B10: =avg_term_months -> 3
A11: PD_annual | B11: =portfolio_PD -> 0.08597
A12: PD_monthly | B12: =portfolio_PD/12 -> 0.0071641667
A13: LGD | B13: =portfolio_LGD -> 0.445
A14: origination_fee_income_kes | B14: =B7*origination_fee -> 17248275
A15: funding_rate_annual | B15: =cost_of_debt -> 0.14
A16: funding_rate_monthly | B16: =B15/12 -> 0.011666667
A17: servicing_rate_monthly | B17: 0.005
A19: LOGIC: Each month — defaults removed from opening balance first. Payment calculated on performing balance only. Closing = performing balance minus principal repaid. Funding cost charged on full opening balance.
A21: month | B21: opening_balance | C21: defaults | D21: performing_balance | E21: scheduled_payment | F21: interest_income | G21: principal_repaid | H21: recoveries | I21: closing balance | J21: gross_revenue | K21: funding_cost | L21: servicing_cost | M21: net_cashflow | N21: cumulative_net
A22: 0 | B22: 0 | C22: 0 | D22: 0 | E22: 0 | F22: 0 | G22: 0 | H22: 0 | I22: =$B$7 -> 287471250 | J22: =$B$14 -> 17248275 | K22: =-$B$7 -> -287471250 | L22: 0 | M22: =J22+K22+L22 -> -270222975 | N22: =M22 -> -270222975
A23: =A22+1 -> 1 | B23: =I22 -> 287471250 | C23: =B23*$B$12 -> 2059491.9 | D23: =B23-C23 -> 2.8541176e+08 | E23: =PMT($B$9,$B$10,-D23) -> 1.0022762e+08 | F23: =D23*$B$9 -> 7569515.8 | G23: =E23-F23 -> 92658106 | H23: =C23*(1-$B$13) -> 1143018 | I23: =D23-G23 -> 1.9275365e+08 | J23: =E23+H23 -> 1.0137064e+08 | K23: =-B23*$B$16 -> -3353831.2 | L23: =-B23*$B$17 -> -1437356.2 | M23: =J23+K23+L23 -> 96579453 | N23: =N22+M23 -> -1.7364352e+08
A24: =A23+1 -> 2 | B24: =I23 -> 1.9275365e+08 | C24: =B24*$B$12 -> 1380919.3 | D24: =B24-C24 -> 1.9137273e+08 | E24: =PMT($B$9,$B$10-1,-D24) -> 99509575 | F24: =D24*$B$9 -> 5075470.4 | G24: =E24-F24 -> 94434104 | H24: =C24*(1-$B$13) -> 766410.2 | I24: =D24-G24 -> 96938628 | J24: =E24+H24 -> 1.0027599e+08 | K24: =-B24*$B$16 -> -2248792.6 | L24: =-B24*$B$17 -> -963768.26 | M24: =J24+K24+L24 -> 97063424 | N24: =N23+M24 -> -76580098
A25: =A24+1 -> 3 | B25: =I24 -> 96938628 | C25: =B25*$B$12 -> 694484.49 | D25: =B25-C25 -> 96244143 | E25: =PMT($B$9,$B$10-2,-D25) -> 98796672 | F25: =D25*$B$9 -> 2552528.2 | G25: =E25-F25 -> 96244143 | H25: =C25*(1-$B$13) -> 385438.89 | I25: =D25-G25 -> 0 | J25: =E25+H25 -> 99182111 | K25: =-B25*$B$16 -> -1130950.7 | L25: =-B25*$B$17 -> -484693.14 | M25: =J25+K25+L25 -> 97566467 | N25: =N24+M25 -> 20986369
A27: VERIFICATION CHECKS
A28: closing_balance_month3 | B28: =I25 -> 0 | C28: =IF(ABS(B28)<B7*0.05,"PASS — near zero","WARNING — check formulas") -> PASS — near zero
A29: total_interest_income | B29: =F23+F24+F25 -> 15197514 | C29: =IF(B29>0,"PASS","WARNING") -> PASS
A30: total_defaults_kes | B30: =C23+C24+C25 -> 4134895.7 | C30: =TEXT(B30/B7,"0.0%") & " of original principal" -> 1.4% of original principal
A31: total_recoveries_kes | B31: =H23+H24+H25 -> 2294867.1
A32: net_credit_loss_kes | B32: =(B30-B31) -> 1840028.6 | C32: =TEXT(B32/B7,"0.0%") & " loss rate" -> 0.6% loss rate
A34: COHORT RETURNS
A35: cohort_IRR_monthly | B35: =IFERROR(IRR(M22:M25),"Negative — check cashflows") -> 0.038283675
A36: cohort_IRR_annual | B36: =(1+B35)^12-1 -> 0.569612
A37: cohort_MOIC | B37: =IFERROR((J22+J23+J24+J25+H23+H24+H25)/$B$7,"Check") -> 1.1144484
A38: payback_in_months | B38: {=IFERROR(MATCH(TRUE,INDEX(N22:N25>=0,0),0)-1,"Beyond term")} -> 3

Sheet PORTFOLIO
A4: COHORT REPAYMENT RATIOS — from LOAN_CASHFLOWS
A5: principal_repaid_month1_ratio | B5: =LOAN_CASHFLOWS!G23/LOAN_CASHFLOWS!B7 -> 0.3223213
A6: principal_repaid_month2_ratio | B6: =LOAN_CASHFLOWS!G24/LOAN_CASHFLOWS!B7 -> 0.3284993
A7: principal_repaid_month3_ratio | B7: =LOAN_CASHFLOWS!G25/LOAN_CASHFLOWS!B7 -> 0.33479572
A8: total_repayment_ratio_check | B8: =SUM(B5:B7) -> 0.98561632 | C8: =IF(ABS(B8-1)<0.05,"PASS — sums to ~100%","WARNING — check LOAN_CASHFLOWS") -> PASS — sums to ~100%
A10: ORIGINATION REFERENCE ROW — KES Millions
A11: new_originations_kes_m | B11: 0 | C11: =MARKET_MODEL!C18/1000000 -> 244.35056 | D11: =MARKET_MODEL!D18/1000000 -> 263.89861 | E11: =MARKET_MODEL!E18/1000000 -> 285.0105 | F11: =MARKET_MODEL!F18/1000000 -> 307.81134 | G11: =MARKET_MODEL!G18/1000000 -> 332.43624 | H11: =MARKET_MODEL!H18/1000000 -> 359.03114 | I11: =MARKET_MODEL!I18/1000000 -> 387.75363 | J11: =MARKET_MODEL!J18/1000000 -> 418.77392 | ... AL11: =MARKET_MODEL!AL18/1000000 -> 3612.8072
A14: Metric | B14: Month 0 | C14: Month 1 | D14: Month 2 | E14: Month 3 | F14: Month 4 | G14: Month 5 | H14: Month 6 | I14: Month 7 | J14: Month 8 | K14: Month 9 | L14: Month 10 | M14: Month 11 | N14: Month 12 | O14: Month 13 | P14: Month 14 | Q14: Month 15 | R14: Month 16 | S14: Month 17 | T14: Month 18 | U14: Month 19 | V14: Month 20 | W14: Month 21 | X14: Month 22 | Y14: Month 23 | Z14: Month 24 | AA14: Month 25 | AB14: Month 26 | AC14: Month 27 | AD14: Month 28 | AE14: Month 29 | AF14: Month 30 | AG14: Month 31 | AH14: Month 32 | AI14: Month 33 | AJ14: Month 34 | AK14: Month 35 | AL14: Month 36
A15: new_originations_kes_m | B15: 0 | C15: =C11 -> 244.35056 | D15: =D11 -> 263.89861 | E15: =E11 -> 285.0105 | F15: =F11 -> 307.81134 | G15: =G11 -> 332.43624 | H15: =H11 -> 359.03114 | I15: =I11 -> 387.75363 | J15: =J11 -> 418.77392 | ... AL15: =AL11 -> 3612.8072
A16: scheduled_repayments_kes_m | B16: 0 | C16: 0 | D16: =IFERROR(C15*$B$5,0) -> 78.75939 | E16: =IFERROR(C15*$B$6 + D15*$B$5, 0) -> 165.32913 | F16: =IFERROR(C15*$B$7 + D15*$B$6 + E15*$B$5, 0) -> 260.36298 | G16: =IFERROR(D15*$B$7 + E15*$B$6 + F15*$B$5, 0) -> 281.19202 | H16: =IFERROR(E15*$B$7 + F15*$B$6 + G15*$B$5, 0) -> 303.68738 | I16: =IFERROR(F15*$B$7 + G15*$B$6 + H15*$B$5, 0) -> 327.98237 | J16: =IFERROR(G15*$B$7 + H15*$B$6 + I15*$B$5, 0) -> 354.22096 | K16: =IFERROR(H15*$B$7 + I15*$B$6 + J15*$B$5, 0) -> 382.55864 | L16: =IFERROR(I15*$B$7 + J15*$B$6 + K15*$B$5, 0) -> 413.16333 | M16: =IFERROR(J15*$B$7 + K15*$B$6 + L15*$B$5, 0) -> 446.2164 | ... AL16: =IFERROR(AI15*$B$7 + AJ15*$B$6 + AK15*$B$5, 0) -> 3055.9019
A17: opening_loanbook_kes_m | B17: 0 | C17: =B20 -> 0 | D17: =C20 -> 244.35056 | E17: =D20 -> 429.48978 | F17: =E20 -> 548.39214 | G17: =F20 -> 594.47126 | H17: =G20 -> 643.96718 | I17: =H20 -> 697.41573 | J17: =I20 -> 755.13399 | ... AL17: =AK20 -> 6692.5075
A18: defaults_kes_m | B18: 0 | C18: =B17*portfolio_PD/12 -> 0 | D18: =C17*portfolio_PD/12 -> 0 | E18: =D17*portfolio_PD/12 -> 1.7505682 | F18: =E17*portfolio_PD/12 -> 3.0769364 | G18: =F17*portfolio_PD/12 -> 3.9287727 | H18: =G17*portfolio_PD/12 -> 4.2588912 | I18: =H17*portfolio_PD/12 -> 4.6134882 | J18: =I17*portfolio_PD/12 -> 4.9964025 | ... AL18: =AK17*portfolio_PD/12 -> 44.382992
A19: recoveries_kes_m | B19: 0 | C19: =C18*(1-portfolio_LGD) -> 0 | D19: =D18*(1-portfolio_LGD) -> 0 | E19: =E18*(1-portfolio_LGD) -> 0.97156533 | F19: =F18*(1-portfolio_LGD) -> 1.7076997 | G19: =G18*(1-portfolio_LGD) -> 2.1804689 | H19: =H18*(1-portfolio_LGD) -> 2.3636846 | I19: =I18*(1-portfolio_LGD) -> 2.5604859 | J19: =J18*(1-portfolio_LGD) -> 2.7730034 | ... AL19: =AL18*(1-portfolio_LGD) -> 24.632561
A20: closing_loanbook_kes_m | B20: 0 | C20: =C17+C15-C16-C18+C19 -> 244.35056 | D20: =D17+D15-D16-D18+D19 -> 429.48978 | E20: =E17+E15-E16-E18+E19 -> 548.39214 | F20: =F17+F15-F16-F18+F19 -> 594.47126 | G20: =G17+G15-G16-G18+G19 -> 643.96718 | H20: =H17+H15-H16-H18+H19 -> 697.41573 | I20: =I17+I15-I16-I18+I19 -> 755.13399 | J20: =J17+J15-J16-J18+J19 -> 817.46355 | ... AL20: =AL17+AL15-AL16-AL18+AL19 -> 7229.6623
A22: — MONTHLY REVENUE AND COSTS —
A23: interest_income_kes_m | B23: 0 | C23: =C17*(RISK_SEGMENTS!$G$9/12) -> 0 | D23: =D17*(RISK_SEGMENTS!$G$9/12) -> 6.480516 | E23: =E17*(RISK_SEGMENTS!$G$9/12) -> 11.390665 | F23: =F17*(RISK_SEGMENTS!$G$9/12) -> 14.544121 | G23: =G17*(RISK_SEGMENTS!$G$9/12) -> 15.766203 | H23: =H17*(RISK_SEGMENTS!$G$9/12) -> 17.078903 | I23: =I17*(RISK_SEGMENTS!$G$9/12) -> 18.496433 | J23: =J17*(RISK_SEGMENTS!$G$9/12) -> 20.027201 | ... AL23: =AL17*(RISK_SEGMENTS!$G$9/12) -> 177.49459
A24: origination_fee_income_kes_m | B24: 0 | C24: =C15*origination_fee -> 14.661034 | D24: =D15*origination_fee -> 15.833916 | E24: =E15*origination_fee -> 17.10063 | F24: =F15*origination_fee -> 18.46868 | G24: =G15*origination_fee -> 19.946175 | H24: =H15*origination_fee -> 21.541869 | I24: =I15*origination_fee -> 23.265218 | J24: =J15*origination_fee -> 25.126435 | ... AL24: =AL15*origination_fee -> 216.76843
A25: total_revenue_kes_m | B25: 0 | C25: =C23+C24 -> 14.661034 | D25: =D23+D24 -> 22.314432 | E25: =E23+E24 -> 28.491295 | F25: =F23+F24 -> 33.012801 | G25: =G23+G24 -> 35.712377 | H25: =H23+H24 -> 38.620772 | I25: =I23+I24 -> 41.761651 | J25: =J23+J24 -> 45.153636 | ... AL25: =AL23+AL24 -> 394.26302
A26: funding_cost_kes_m | B26: 0 | C26: =-C17*(cost_of_debt/12) -> 0 | D26: =-D17*(cost_of_debt/12) -> -2.8507566 | E26: =-E17*(cost_of_debt/12) -> -5.0107141 | F26: =-F17*(cost_of_debt/12) -> -6.3979083 | G26: =-G17*(cost_of_debt/12) -> -6.935498 | H26: =-H17*(cost_of_debt/12) -> -7.5129504 | I26: =-I17*(cost_of_debt/12) -> -8.1365168 | J26: =-J17*(cost_of_debt/12) -> -8.8098965 | ... AL26: =-AL17*(cost_of_debt/12) -> -78.079254
A27: CAC_total_kes_m | B27: 0 | C27: =-C15*CAC_blended/1000000 -> -0.15589566 | D27: =-D15*CAC_blended/1000000 -> -0.16836731 | E27: =-E15*CAC_blended/1000000 -> -0.1818367 | F27: =-F15*CAC_blended/1000000 -> -0.19638363 | G27: =-G15*CAC_blended/1000000 -> -0.21209432 | H27: =-H15*CAC_blended/1000000 -> -0.22906187 | I27: =-I15*CAC_blended/1000000 -> -0.24738682 | J27: =-J15*CAC_blended/1000000 -> -0.26717776 | ... AL27: =-AL15*CAC_blended/1000000 -> -2.304971
A28: servicing_cost_kes_m | B28: 0 | C28: =-C17*0.005 -> 0 | D28: =-D17*0.005 -> -1.2217528 | E28: =-E17*0.005 -> -2.1474489 | F28: =-F17*0.005 -> -2.7419607 | G28: =-G17*0.005 -> -2.9723563 | H28: =-H17*0.005 -> -3.2198359 | I28: =-I17*0.005 -> -3.4870786 | J28: =-J17*0.005 -> -3.7756699 | ... AL28: =-AL17*0.005 -> -33.462538
A29: net_credit_loss_kes_m | B29: 0 | C29: =-(C18-C19) -> 0 | D29: =-(D18-D19) -> 0 | E29: =-(E18-E19) -> -0.77900283 | F29: =-(F18-F19) -> -1.3692367 | G29: =-(G18-G19) -> -1.7483039 | H29: =-(H18-H19) -> -1.8952066 | I29: =-(I18-I19) -> -2.0530022 | J29: =-(J18-J19) -> -2.2233991 | ... AL29: =-(AL18-AL19) -> -19.750431
A30: net_contribution_kes_m | B30: 0 | C30: =C25+C26+C27+C28+C29 -> 14.505138 | D30: =D25+D26+D27+D28+D29 -> 18.073556 | E30: =E25+E26+E27+E28+E29 -> 20.372292 | F30: =F25+F26+F27+F28+F29 -> 22.307311 | G30: =G25+G26+G27+G28+G29 -> 23.844125 | H30: =H25+H26+H27+H28+H29 -> 25.763717 | I30: =I25+I26+I27+I28+I29 -> 27.837666 | J30: =J25+J26+J27+J28+J29 -> 30.077493 | ... AL30: =AL25+AL26+AL27+AL28+AL29 -> 260.66582
A32: — PORTFOLIO HEALTH METRICS —
A33: npl_ratio_pct | B33: 0 | C33: =IFERROR(C18/C20,0) -> 0 | D33: =IFERROR(D18/D20,0) -> 0 | E33: =IFERROR(E18/E20,0) -> 0.0031921831 | F33: =IFERROR(F18/F20,0) -> 0.0051759212 | G33: =IFERROR(G18/G20,0) -> 0.0061008897 | H33: =IFERROR(H18/H20,0) -> 0.006106675 | I33: =IFERROR(I18/I20,0) -> 0.0061094961 | J33: =IFERROR(J18/J20,0) -> 0.0061120799 | ... AL33: =IFERROR(AL18/AL20,0) -> 0.0061390131
A34: portfolio_yield_annualised | B34: =RISK_SEGMENTS!G9 -> 0.31825665 | C34: =$B$34 -> 0.31825665 | D34: =$B$34 -> 0.31825665 | E34: =$B$34 -> 0.31825665 | F34: =$B$34 -> 0.31825665 | G34: =$B$34 -> 0.31825665 | H34: =$B$34 -> 0.31825665 | I34: =$B$34 -> 0.31825665 | J34: =$B$34 -> 0.31825665 | ... AL34: =$B$34 -> 0.31825665
A35: net_credit_loss_rate | B35: 0 | C35: =IFERROR((C18-C19)/C20,0) -> 0 | D35: =IFERROR((D18-D19)/D20,0) -> 0 | E35: =IFERROR((E18-E19)/E20,0) -> 0.0014205215 | F35: =IFERROR((F18-F19)/F20,0) -> 0.0023032849 | G35: =IFERROR((G18-G19)/G20,0) -> 0.0027148959 | H35: =IFERROR((H18-H19)/H20,0) -> 0.0027174704 | I35: =IFERROR((I18-I19)/I20,0) -> 0.0027187258 | J35: =IFERROR((J18-J19)/J20,0) -> 0.0027198756 | ... AL35: =IFERROR((AL18-AL19)/AL20,0) -> 0.0027318608
A36: cost_of_risk_annualised | B36: 0 | C36: =IFERROR(C29/C20*12,0) -> 0 | D36: =IFERROR(D29/D20*12,0) -> 0 | E36: =IFERROR(E29/E20*12,0) -> -0.017046258 | F36: =IFERROR(F29/F20*12,0) -> -0.027639419 | G36: =IFERROR(G29/G20*12,0) -> -0.032578751 | H36: =IFERROR(H29/H20*12,0) -> -0.032609644 | I36: =IFERROR(I29/I20*12,0) -> -0.032624709 | J36: =IFERROR(J29/J20*12,0) -> -0.032638507 | ... AL36: =IFERROR(AL29/AL20*12,0) -> -0.03278233
A37: return_on_portfolio_monthly | B37: 0 | C37: =IFERROR(C30/C17,0) -> 0 | D37: =IFERROR(D30/D17,0) -> 0.073965681 | E37: =IFERROR(E30/E17,0) -> 0.047433706 | F37: =IFERROR(F30/F17,0) -> 0.040677664 | G37: =IFERROR(G30/G17,0) -> 0.040109802 | H37: =IFERROR(H30/H17,0) -> 0.040007811 | I37: =IFERROR(I30/I17,0) -> 0.039915455 | J37: =IFERROR(J30/J17,0) -> 0.039830671 | ... AL37: =IFERROR(AL30/AL17,0) -> 0.038948902
A39: VERIFICATION CHECKS
A40: max_loanbook_kes_m | B40: =MAX(C20:AL20) -> 7229.6623 | C40: =IF(B40>0,"PASS — portfolio growing","WARNING — portfolio not growing") -> PASS — portfolio growing
A41: month_loanbook_peaks | B41: =MATCH(MAX(C20:AL20),C20:AL20,0)+1 -> 37
A42: total_revenue_36_months_kes_m | B42: =SUM(C25:AL25) -> 4955.6412
A43: total_net_contribution_kes_m | B43: =SUM(C30:AL30) -> 3291.4411 | C43: =IF(B43>0,"PASS — profitable","WARNING — loss-making") -> PASS — profitable
A44: breakeven_month | B44: {=MATCH(TRUE, C30:AL30>0, 0)} -> 1

Sheet INCOME_STATEMENT
A1: INCOME STATEMENT — 3 Year Projection
A2: All values KES Millions
B4: Year 1 | C4: Year 2 | D4: Year 3 | E4: 3 Year Total
A6: REVENUE
A7: Interest Income | B7: =SUM(PORTFOLIO!C23:N23) -> 201.79802 | C7: =SUM(PORTFOLIO!O23:Z23) -> 568.38894 | D7: =SUM(PORTFOLIO!AA23:AL23) -> 1442.3433 | E7: =SUM(B7:D7) -> 2212.5303
A8: Origination Fee Income | B8: =SUM(PORTFOLIO!C24:N24) -> 278.22429 | C8: =SUM(PORTFOLIO!O24:Z24) -> 700.6161 | D8: =SUM(PORTFOLIO!AA24:AL24) -> 1764.2705 | E8: =SUM(B8:D8) -> 2743.1109
A9: TOTAL REVENUE | B9: =B7+B8 -> 480.02231 | C9: =C7+C8 -> 1269.005 | D9: =D7+D8 -> 3206.6138 | E9: =E7+E8 -> 4955.6412
A11: COSTS
A12: Funding Cost | B12: =SUM(PORTFOLIO!C26:N26) -> -88.77025 | C12: =SUM(PORTFOLIO!O26:Z26) -> -250.03233 | D12: =SUM(PORTFOLIO!AA26:AL26) -> -634.48183 | E12: =SUM(B12:D12) -> -973.28441
A13: Customer Acquisition Cost | B13: =SUM(PORTFOLIO!C27:N27) -> -2.9584516 | C13: =SUM(PORTFOLIO!O27:Z27) -> -7.4498845 | D13: =SUM(PORTFOLIO!AA27:AL27) -> -18.760077 | E13: =SUM(B13:D13) -> -29.168413
A14: Servicing Cost | B14: =SUM(PORTFOLIO!C28:N28) -> -38.044393 | C14: =SUM(PORTFOLIO!O28:Z28) -> -107.15671 | D14: =SUM(PORTFOLIO!AA28:AL28) -> -271.92078 | E14: =SUM(B14:D14) -> -417.12189
A15: Net Credit Losses | B15: =SUM(PORTFOLIO!C29:N29) -> -20.954823 | C15: =SUM(PORTFOLIO!O29:Z29) -> -63.197285 | D15: =SUM(PORTFOLIO!AA29:AL29) -> -160.47325 | E15: =SUM(B15:D15) -> -244.62536
A16: TOTAL COSTS | B16: =B12+B13+B14+B15 -> -150.72792 | C16: =C12+C13+C14+C15 -> -427.83621 | D16: =D12+D13+D14+D15 -> -1085.6359 | E16: =E12+E13+E14+E15 -> -1664.2001
A18: EBITDA | B18: =B9+B16 -> 329.29439 | C18: =C9+C16 -> 841.16882 | D18: =D9+D16 -> 2120.9779 | E18: =E9+E16 -> 3291.4411
A19: Tax (30%) | B19: =IF(B18>0,-B18*tax_rate,0) -> -98.788317 | C19: =IF(C18>0,-C18*tax_rate,0) -> -252.35065 | D19: =IF(D18>0,-D18*tax_rate,0) -> -636.29336 | E19: =IF(E18>0,-E18*tax_rate,0) -> -987.43233
A20: NET INCOME | B20: =B18+B19 -> 230.50607 | C20: =C18+C19 -> 588.81818 | D20: =D18+D19 -> 1484.6845 | E20: =E18+E19 -> 2304.0088
A22: KEY METRICS
A23: Net Margin % | B23: =IFERROR(B20/B9,0) -> 0.48019867 | C23: =IFERROR(C20/C9,0) -> 0.46399988 | D23: =IFERROR(D20/D9,0) -> 0.46300696 | E23: =IFERROR(E20/E9,0) -> 0.46492647
A24: Cost Income Ratio | B24: =IFERROR(ABS(B16)/B9,0) -> 0.3140019 | C24: =IFERROR(ABS(C16)/C9,0) -> 0.33714304 | D24: =IFERROR(ABS(D16)/D9,0) -> 0.33856149 | E24: =IFERROR(ABS(E16)/E9,0) -> 0.33581933
A25: Return on Portfolio | B25: =IFERROR(B20/AVERAGE(PORTFOLIO!C20:N20),0) -> 0.31686103 | C25: =IFERROR(C20/AVERAGE(PORTFOLIO!O20:Z20),0) -> 0.30498027 | D25: =IFERROR(D20/AVERAGE(PORTFOLIO!AA20:AL20),0) -> 0.30322211

Sheet INVESTOR_RETURNS
A1: INVESTOR RETURNS — Equity Fund Perspective
A2: Decision framework: Base IRR > 25% | Recession IRR > 10% | Capital loss probability < 20%
A3: All values in KES Millions unless stated
A5: CAPITAL STRUCTURE
A6: peak_loanbook_kes_m | B6: =PORTFOLIO!B40 -> 7229.6623 | C6: Largest single month loanbook
A7: equity_required_kes_m | B7: =B6*equity_ratio -> 2168.8987 | C7: 30% of peak loanbook
A8: debt_facility_required_kes_m | B8: =B6*(1-equity_ratio) -> 5060.7636 | C8: 70% of peak loanbook
A9: total_capital_deployed_kes_m | B9: =B7+B8 -> 7229.6623 | C9: Full facility size
A10: Equity as % of total capital | B10: =B7/B9 -> 0.3 | C10: Should equal equity_ratio assumption
A12: INCOME SUMMARY — FROM INCOME STATEMENT
B13: Year 1 | C13: Year 2 | D13: Year 3 | E13: 3 Year Total
A14: Total Revenue (KES M) | B14: =INCOME_STATEMENT!B$9 -> 480.02231 | C14: =INCOME_STATEMENT!C$9 -> 1269.005 | D14: =INCOME_STATEMENT!D$9 -> 3206.6138 | E14: =INCOME_STATEMENT!E$9 -> 4955.6412
A15: Total Costs (KES M) | B15: =INCOME_STATEMENT!B$16 -> -150.72792 | C15: =INCOME_STATEMENT!C$16 -> -427.83621 | D15: =INCOME_STATEMENT!D$16 -> -1085.6359 | E15: =INCOME_STATEMENT!E$16 -> -1664.2001
A16: EBITDA (KES M) | B16: =INCOME_STATEMENT!B$18 -> 329.29439 | C16: =INCOME_STATEMENT!C$18 -> 841.16882 | D16: =INCOME_STATEMENT!D$18 -> 2120.9779 | E16: =INCOME_STATEMENT!E$18 -> 3291.4411
A17: Net Income (KES M) | B17: =INCOME_STATEMENT!B$20 -> 230.50607 | C17: =INCOME_STATEMENT!C$20 -> 588.81818 | D17: =INCOME_STATEMENT!D$20 -> 1484.6845 | E17: =INCOME_STATEMENT!E$20 -> 2304.0088
A18: Net Margin % | B18: =INCOME_STATEMENT!B$23 -> 0.48019867 | C18: =INCOME_STATEMENT!C$23 -> 0.46399988 | D18: =INCOME_STATEMENT!D$23 -> 0.46300696 | E18: =IFERROR(E17/E14,0) -> 0.46492647
A20: EXIT AND TERMINAL VALUE
A21: Year 3 EBITDA (KES M) | B21: =INCOME_STATEMENT!D18 -> 2120.9779 | C21: From income statement
A22: Exit EBITDA multiple | B22: =exit_multiple_ebitda -> 8 | C22: From assumptions - 8X
A23: Enterprise terminal value (KES M) | B23: =B21*B22 -> 16967.823 | C23: Total company value at exit
A24: Less: debt outstanding (KES M) | B24: =-B8*(1-SUM(PORTFOLIO!C16:AL16)/SUM(PORTFOLIO!C15:AL15)) -> -827.35853 | C24: Remaining debt at exit
A25: Equity terminal value (KES M) | B25: =B23+B24 -> 16140.464 | C25: What equity investors receive
A27: EQUITY CASHFLOW SCHEDULE — For IRR Calculation
A28: Dividend policy: 50% of net income distributed annually 50% retained for portfolio growth capital
A30: Year 0 - equity deployed | B30: =-B7 -> -2168.8987 | C30: Cash out at fund close
A31: Year 1 - dividend received | B31: =IF(B17>0,B17*0.5,0) -> 115.25304 | C31: 50% of Year 1 net income
A32: Year 2 - dividend received | B32: =IF(C17>0,C17*0.5,0) -> 294.40909 | C32: 50% of Year 2 net income
A33: Year 3 - dividend plus exit proceeds | B33: =IF(D17>0,D17*0.5,0)+B25 -> 16882.807 | C33: Year 3 dividend plus equity terminal value
A35: RETURN METRICS
A36: Gross IRR | B36: =IFERROR(IRR(B30:B33),"Check cashflows — may need more years") -> 1.0227431 | C36: Equity IRR before tax
A37: Net IRR after tax | B37: =IFERROR(B36*(1-tax_rate),"Check B36") -> 0.7159202 | C37: After 30% Kenya corporate tax
A38: MOIC | B38: =IFERROR((B31+B32+B33)/(-B30),"Check cashflows") -> 7.972926 | C38: Total money returned per KES invested
A39: DPI | B39: =IFERROR((B31+B32)/(-B30),"Check") -> 0.18888025 | C39: Dividends only - before exit
A40: TVPI | B40: =IFERROR((B31+B32+B25)/(-B30),"Check") -> 7.6306591 | C40: Total value including unrealised exit
A41: Payback period | B41: =IF(B31>=-B30,1,IF(B31+B32>=-B30,2,IF(B31+B32+B33>=-B30,3,"Beyond Year 3"))) -> 3 | C41: Years to return invested capital
A43: INVESTMENT DECISION FRAMEWORK
A44: Criterion | B44: Threshold | C44: Actual | D44: Result
A45: Base case gross IRR | B45: >25% | C45: =B36 -> 1.0227431 | D45: =IF(B36>target_IRR,"✓ PASS","✗ FAIL") -> ✓ PASS
A46: Net IRR after tax | B46: >15% | C46: =B37 -> 0.7159202 | D46: =IF(B37>0.15,"✓ PASS","✗ FAIL") -> ✓ PASS
A47: MOIC | B47: >2.5% | C47: =B38 -> 7.972926 | D47: =IF(B38>2.5,"✓ PASS","✗ FAIL") -> ✓ PASS
...

Sheet STRESS_TEST
A1: STRESS TEST — Scenario Analysis and Downside Protection
A2: Four scenarios tested: Base | Mild Recession | Severe Recession | APR Cap Shock
A3: Elasticities from ASSUMPTIONS sheet — calibrated to CBK NPL historical data
A5: SCENARIO DEFINITIONS
A6: Scenario | B6: Base Case | C6: Mild Recession | D6: Severe Recession | E6: APR Cap Shock
A7: unemployment_shock_pp | B7: 0 | C7: 2 | D7: 5 | E7: 0
A8: inflation_shock_PP | B8: 0 | C8: 3 | D8: 6 | E8: 0
A9: rate_hike_pp | B9: 0 | C9: 1.5 | D9: 4 | E9: 0
A10: apr_cap_reduction_pp | B10: 0 | C10: 0 | D10: 0 | E10: 8
A11: Scenario description | B11: Normal operations | C11: Modertate macro stress | D11: 2008-style crisis | E11: Regulator caps APR
A12: Historical precedent | B12: Baseline 2024 | C12: Kenya 2017 drought | D12: Kenya 2008 crisis | E12: Kenya 2016 rate cap
A14: PROBABILITY OF DEFAULT — STRESSED
A15: Formula: Base PD × (1 + unemployment elasticity × shock + inflation elasticity × shock + rate elasticity × shock)
A16: PD_prime_stressed | B16: =PD_prime -> 0.032 | C16: =PD_prime*(1+unemp_elasticity*C7+inflation_elasticity*C8+rate_elasticity*C9) -> 0.05696 | D16: =PD_prime*(1+unemp_elasticity*D7+inflation_elasticity*D8+rate_elasticity*D9) -> 0.09152 | E16: =PD_prime -> 0.032
A17: PD_nearprime_stressed | B17: =PD_nearprime -> 0.077 | C17: =PD_nearprime*(1+unemp_elasticity*C7+inflation_elasticity*C8+rate_elasticity*C9) -> 0.13706 | D17: =PD_nearprime*(1+unemp_elasticity*D7+inflation_elasticity*D8+rate_elasticity*D9) -> 0.22022 | E17: =PD_nearprime -> 0.077
A18: PD_subprime_stressed | B18: =PD_subprime -> 0.2006 | C18: =PD_subprime*(1+unemp_elasticity*C7+inflation_elasticity*C8+rate_elasticity*C9) -> 0.357068 | D18: =PD_subprime*(1+unemp_elasticity*D7+inflation_elasticity*D8+rate_elasticity*D9) -> 0.573716 | E18: =PD_subprime -> 0.2006
A19: portfolio_PD_stressed | B19: =SUMPRODUCT(B16:B18,ASSUMPTIONS!B40:B42) -> 0.08597 | C19: =SUMPRODUCT(C16:C18,ASSUMPTIONS!B40:B42) -> 0.1530266 | D19: =SUMPRODUCT(D16:D18,ASSUMPTIONS!B40:B42) -> 0.2458742 | E19: =SUMPRODUCT(E16:E18,ASSUMPTIONS!B40:B42) -> 0.08597
A20: PD uplift vs base | B20: =0 -> 0 | C20: =C19-B19 -> 0.0670566 | D20: =D19-B19 -> 0.1599042 | E20: =E19-B19 -> 0
A22: LOSS GIVEN DEFAULT — STRESSED
A23: LGD_stressed | B23: =portfolio_LGD -> 0.445 | C23: =portfolio_LGD -> 0.445 | D23: =portfolio_LGD+LGD_recession_uplift -> 0.545 | E23: =portfolio_LGD -> 0.445
A24: Expected loss stressed | B24: =B19*B23 -> 0.03825665 | C24: =C19*C23 -> 0.068096837 | D24: =D19*D23 -> 0.13400144 | E24: =E19*E23 -> 0.03825665
A25: EL uplift vs base | B25: =0 -> 0 | C25: =C24-B24 -> 0.029840187 | D25: =D24-B24 -> 0.095744789 | E25: =E24-B24 -> 0
A27: REVENUE AND PRICING — STRESSED
A28: Effective APR | B28: =RISK_SEGMENTS!G9 -> 0.31825665 | C28: =B28 -> 0.31825665 | D28: =B28 -> 0.31825665 | E28: =MAX(B28-(E10/100),cost_of_debt+0.02) -> 0.23825665
A29: Revenue multiplier | B29: 1 | C29: 1 | D29: 0.93 | E29: =E28/B28 -> 0.74863055
A30: APR reduction | B30: =0 -> 0 | C30: =0 -> 0 | D30: =0 -> 0 | E30: =B28-E28 -> 0.08 | F30: Severe recession: 7% revenue haircut from concession programs and fee waivers
A32: STRESSED IRR DERIVATION
A33: Method: Scales base IRR by credit loss ratio and revenue multiplier Base IRR from INVESTOR_RETURNS sheet
A34: Base credit loss rate | B34: =portfolio_PD*portfolio_LGD -> 0.03825665 | C34: =B34 -> 0.03825665 | D34: =B34 -> 0.03825665 | E34: =B34 -> 0.03825665
A35: Stressed credit loss rate | B35: =B34 -> 0.03825665 | C35: =C19*C23 -> 0.068096837 | D35: =D19*D23 -> 0.13400144 | E35: =E19*E23 -> 0.03825665
A36: Credit loss ratio | B36: =1 -> 1 | C36: =IFERROR(B35/C35,1) -> 0.56179775 | D36: =IFERROR(B35/D35,1) -> 0.28549432 | E36: =1 -> 1
A37: Revenue multiplier | B37: =1 -> 1 | C37: =C29 -> 1 | D37: =D29 -> 0.93 | E37: =E29 -> 0.74863055
A38: Stressed IRR | B38: =INVESTOR_RETURNS!B36 -> 1.0227431 | C38: =IFERROR(B38*C36*C37,0) -> 0.5745748 | D38: =IFERROR(B38*D36*D37,0) -> 0.27154825 | E38: =IFERROR(B38*E36*E37,0) -> 0.76565676
A39: IRR delta vs base | B39: =0 -> 0 | C39: =C38-B38 -> -0.44816835 | D39: =D38-B38 -> -0.7511949 | E39: =E38-B38 -> -0.25708639
A40: Stressed net IRR after tax | B40: =INVESTOR_RETURNS!B37 -> 0.7159202 | C40: =C38*(1-tax_rate) -> 0.40220236 | D40: =D38*(1-tax_rate) -> 0.19008377 | E40: =E38*(1-tax_rate) -> 0.53595973
A42: MOIC UNDER STRESS
A43: Stressed MOIC | B43: =INVESTOR_RETURNS!B38 -> 7.972926 | C43: =INVESTOR_RETURNS!B38*C37*C36 -> 4.4791719 | D43: =INVESTOR_RETURNS!B38*D37*D36 -> 2.1168893 | E43: =INVESTOR_RETURNS!B38*E37*E36 -> 5.968776
A45: DOWNSIDE PROTECTION ASSESSMENT
A46: Gross IRR above 25% hurdle | B46: =IF(B38>target_IRR,"✓","✗") -> ✓ | C46: =IF(C38>target_IRR,"✓","✗") -> ✓ | D46: =IF(D38>target_IRR,"✓","✗") -> ✓ | E46: =IF(E38>target_IRR,"✓","✗") -> ✓
A47: Gross IRR above 10% floor | B47: =IF(B38>0.1,"✓","✗") -> ✓ | C47: =IF(C38>0.1,"✓","✗") -> ✓ | D47: =IF(D38>0.1,"✓","✗") -> ✓ | E47: =IF(E38>0.1,"✓","✗") -> ✓
...
